Workbook

Sheet Cómo usar
B2: Plantilla de control de inventario
B3: Entradas, salidas, existencias, alertas de reorden y kardex por artículo. Gratis, sin macros.
B6: Cómo se usa
B7: 1. En Productos, da de alta cada artículo con una clave única, su costo, su stock mínimo (y máximo, si lo manejas) y la existencia con la que arrancas.
B8: 2. En Movimientos, captura una fila por cada entrada (compra, devolución de cliente) o salida (venta, consumo, merma), en orden de fecha.
B9: 3. Las existencias, el valor del inventario y el estado (OK, Reordenar, Agotado) se calculan solos en Productos.
B10: 4. En Resumen ves los totales del mes y la lista de compras sugerida; en Kardex, el historial completo de un artículo.
B11: 5. Los datos que trae son de ejemplo: bórralos de Productos (columnas A a I) y de Movimientos (A, B, C, F, J, K y L) antes de empezar.
B13: Colores
B14: Celdas amarillas: aquí capturas.
B15: Celdas grises: fórmulas. No las borres ni escribas encima; si se rompe una, cópiala de la fila de arriba.
B17: Buenas prácticas
... B29: Puedes usarla y compartirla libremente; si la publicas en tu sitio, enlaza a la guía de arriba.

Sheet Resumen
A1: Resumen del inventario
A2: Se actualiza solo con lo que captures en Productos y Movimientos.
B4: Mes a revisar | C4: 46296
B6: Artículos en el catálogo | C6: =COUNTA(Productos!$A$5:$A$504) -> 8
B7: Valor total del inventario | C7: =SUM(Productos!$M$5:$M$504) -> 38581
B8: Artículos por reordenar | C8: =COUNTIF(Productos!$N$5:$N$504,"Reordenar") -> 4
B9: Artículos agotados | C9: =COUNTIF(Productos!$N$5:$N$504,"Agotado") -> 1
B10: Movimientos de entrada en el mes | C10: =COUNTIFS(Movimientos!$B$5:$B$3004,"Entrada",Movimientos!$A$5:$A$3004,">="&DATE(YEAR($C$4),MONTH($C$4),1),Movimientos!$A$5:$A$3004,"<"&EDATE(DATE(YEAR($C$4),MONTH($C$4),1),1)) -> 4
B11: Movimientos de salida en el mes | C11: =COUNTIFS(Movimientos!$B$5:$B$3004,"Salida",Movimientos!$A$5:$A$3004,">="&DATE(YEAR($C$4),MONTH($C$4),1),Movimientos!$A$5:$A$3004,"<"&EDATE(DATE(YEAR($C$4),MONTH($C$4),1),1)) -> 10
B12: Valor de las entradas del mes | C12: =SUMIFS(Movimientos!$H$5:$H$3004,Movimientos!$B$5:$B$3004,"Entrada",Movimientos!$A$5:$A$3004,">="&DATE(YEAR($C$4),MONTH($C$4),1),Movimientos!$A$5:$A$3004,"<"&EDATE(DATE(YEAR($C$4),MONTH($C$4),1),1)) -> 36990
B13: Valor de las salidas del mes | C13: =SUMIFS(Movimientos!$H$5:$H$3004,Movimientos!$B$5:$B$3004,"Salida",Movimientos!$A$5:$A$3004,">="&DATE(YEAR($C$4),MONTH($C$4),1),Movimientos!$A$5:$A$3004,"<"&EDATE(DATE(YEAR($C$4),MONTH($C$4),1),1)) -> 78609
B15: Lista de compras sugerida | D15: Artículos agotados o en su mínimo. Sugerido = llevarlo al stock máximo (o al doble del mínimo si no capturaste máximo).
B16: # | C16: Clave | D16: Descripción | E16: Existencia | F16: Mínimo | G16: Estado | H16: Sugerido comprar
B17: =IF(1<=COUNTIF(Productos!$O$5:$O$504,">0"),1,"") -> 1 | C17: =IF($B17="","",INDEX(Productos!$A$5:$A$504,MATCH($B17,Productos!$O$5:$O$504,0))) -> P-002 | D17: =IF($B17="","",INDEX(Productos!$B$5:$B$504,MATCH($B17,Productos!$O$5:$O$504,0))) -> Varilla corrugada 3/8" | E17: =IF($B17="","",INDEX(Productos!$L$5:$L$504,MATCH($B17,Productos!$O$5:$O$504,0))) -> 60 | F17: =IF($B17="","",INDEX(Productos!$G$5:$G$504,MATCH($B17,Productos!$O$5:$O$504,0))) -> 100 | G17: =IF($B17="","",INDEX(Productos!$N$5:$N$504,MATCH($B17,Productos!$O$5:$O$504,0))) -> Reordenar | H17: =IF($B17="","",MAX(0,IF(N(INDEX(Productos!$H$5:$H$504,MATCH($B17,Productos!$O$5:$O$504,0)))>0,N(INDEX(Productos!$H$5:$H$504,MATCH($B17,Productos!$O$5:$O$504,0))),2*N(F17))-E17)) -> 240
B18: =IF(2<=COUNTIF(Productos!$O$5:$O$504,">0"),2,"") -> 2 | C18: =IF($B18="","",INDEX(Productos!$A$5:$A$504,MATCH($B18,Productos!$O$5:$O$504,0))) -> P-003 | D18: =IF($B18="","",INDEX(Productos!$B$5:$B$504,MATCH($B18,Productos!$O$5:$O$504,0))) -> Block de concreto 15x20x40 | E18: =IF($B18="","",INDEX(Productos!$L$5:$L$504,MATCH($B18,Productos!$O$5:$O$504,0))) -> 420 | F18: =IF($B18="","",INDEX(Productos!$G$5:$G$504,MATCH($B18,Productos!$O$5:$O$504,0))) -> 500 | G18: =IF($B18="","",INDEX(Productos!$N$5:$N$504,MATCH($B18,Productos!$O$5:$O$504,0))) -> Reordenar | H18: =IF($B18="","",MAX(0,IF(N(INDEX(Productos!$H$5:$H$504,MATCH($B18,Productos!$O$5:$O$504,0)))>0,N(INDEX(Productos!$H$5:$H$504,MATCH($B18,Productos!$O$5:$O$504,0))),2*N(F18))-E18)) -> 1580
B19: =IF(3<=COUNTIF(Productos!$O$5:$O$504,">0"),3,"") -> 3 | C19: =IF($B19="","",INDEX(Productos!$A$5:$A$504,MATCH($B19,Productos!$O$5:$O$504,0))) -> P-005 | D19: =IF($B19="","",INDEX(Productos!$B$5:$B$504,MATCH($B19,Productos!$O$5:$O$504,0))) -> Pintura vinílica blanca 19 L | E19: =IF($B19="","",INDEX(Productos!$L$5:$L$504,MATCH($B19,Productos!$O$5:$O$504,0))) -> 4 | F19: =IF($B19="","",INDEX(Productos!$G$5:$G$504,MATCH($B19,Productos!$O$5:$O$504,0))) -> 5 | G19: =IF($B19="","",INDEX(Productos!$N$5:$N$504,MATCH($B19,Productos!$O$5:$O$504,0))) -> Reordenar | H19: =IF($B19="","",MAX(0,IF(N(INDEX(Productos!$H$5:$H$504,MATCH($B19,Productos!$O$5:$O$504,0)))>0,N(INDEX(Productos!$H$5:$H$504,MATCH($B19,Productos!$O$5:$O$504,0))),2*N(F19))-E19)) -> 16
B20: =IF(4<=COUNTIF(Productos!$O$5:$O$504,">0"),4,"") -> 4 | C20: =IF($B20="","",INDEX(Productos!$A$5:$A$504,MATCH($B20,Productos!$O$5:$O$504,0))) -> P-006 | D20: =IF($B20="","",INDEX(Productos!$B$5:$B$504,MATCH($B20,Productos!$O$5:$O$504,0))) -> Alambre recocido | E20: =IF($B20="","",INDEX(Productos!$L$5:$L$504,MATCH($B20,Productos!$O$5:$O$504,0))) -> 35 | F20: =IF($B20="","",INDEX(Productos!$G$5:$G$504,MATCH($B20,Productos!$O$5:$O$504,0))) -> 50 | G20: =IF($B20="","",INDEX(Productos!$N$5:$N$504,MATCH($B20,Productos!$O$5:$O$504,0))) -> Reordenar | H20: =IF($B20="","",MAX(0,IF(N(INDEX(Productos!$H$5:$H$504,MATCH($B20,Productos!$O$5:$O$504,0)))>0,N(INDEX(Productos!$H$5:$H$504,MATCH($B20,Productos!$O$5:$O$504,0))),2*N(F20))-E20)) -> 165
B21: =IF(5<=COUNTIF(Productos!$O$5:$O$504,">0"),5,"") -> 5 | C21: =IF($B21="","",INDEX(Productos!$A$5:$A$504,MATCH($B21,Productos!$O$5:$O$504,0))) -> P-007 | D21: =IF($B21="","",INDEX(Productos!$B$5:$B$504,MATCH($B21,Productos!$O$5:$O$504,0))) -> Cable THW calibre 12 | E21: =IF($B21="","",INDEX(Productos!$L$5:$L$504,MATCH($B21,Productos!$O$5:$O$504,0))) -> 0 | F21: =IF($B21="","",INDEX(Productos!$G$5:$G$504,MATCH($B21,Productos!$O$5:$O$504,0))) -> 4 | G21: =IF($B21="","",INDEX(Productos!$N$5:$N$504,MATCH($B21,Productos!$O$5:$O$504,0))) -> Agotado | H21: =IF($B21="","",MAX(0,IF(N(INDEX(Productos!$H$5:$H$504,MATCH($B21,Productos!$O$5:$O$504,0)))>0,N(INDEX(Productos!$H$5:$H$504,MATCH($B21,Productos!$O$5:$O$504,0))),2*N(F21))-E21)) -> 12
B22: =IF(6<=COUNTIF(Productos!$O$5:$O$504,">0"),6,"") | C22: =IF($B22="","",INDEX(Productos!$A$5:$A$504,MATCH($B22,Productos!$O$5:$O$504,0))) | D22: =IF($B22="","",INDEX(Productos!$B$5:$B$504,MATCH($B22,Productos!$O$5:$O$504,0))) | E22: =IF($B22="","",INDEX(Productos!$L$5:$L$504,MATCH($B22,Productos!$O$5:$O$504,0))) | F22: =IF($B22="","",INDEX(Productos!$G$5:$G$504,MATCH($B22,Productos!$O$5:$O$504,0))) | G22: =IF($B22="","",INDEX(Productos!$N$5:$N$504,MATCH($B22,Productos!$O$5:$O$504,0))) | H22: =IF($B22="","",MAX(0,IF(N(INDEX(Productos!$H$5:$H$504,MATCH($B22,Productos!$O$5:$O$504,0)))>0,N(INDEX(Productos!$H$5:$H$504,MATCH($B22,Productos!$O$5:$O$504,0))),2*N(F22))-E22))
B23: =IF(7<=COUNTIF(Productos!$O$5:$O$504,">0"),7,"") | C23: =IF($B23="","",INDEX(Productos!$A$5:$A$504,MATCH($B23,Productos!$O$5:$O$504,0))) | D23: =IF($B23="","",INDEX(Productos!$B$5:$B$504,MATCH($B23,Productos!$O$5:$O$504,0))) | E23: =IF($B23="","",INDEX(Productos!$L$5:$L$504,MATCH($B23,Productos!$O$5:$O$504,0))) | F23: =IF($B23="","",INDEX(Productos!$G$5:$G$504,MATCH($B23,Productos!$O$5:$O$504,0))) | G23: =IF($B23="","",INDEX(Productos!$N$5:$N$504,MATCH($B23,Productos!$O$5:$O$504,0))) | H23: =IF($B23="","",MAX(0,IF(N(INDEX(Productos!$H$5:$H$504,MATCH($B23,Productos!$O$5:$O$504,0)))>0,N(INDEX(Productos!$H$5:$H$504,MATCH($B23,Productos!$O$5:$O$504,0))),2*N(F23))-E23))
B24: =IF(8<=COUNTIF(Productos!$O$5:$O$504,">0"),8,"") | C24: =IF($B24="","",INDEX(Productos!$A$5:$A$504,MATCH($B24,Productos!$O$5:$O$504,0))) | D24: =IF($B24="","",INDEX(Productos!$B$5:$B$504,MATCH($B24,Productos!$O$5:$O$504,0))) | E24: =IF($B24="","",INDEX(Productos!$L$5:$L$504,MATCH($B24,Productos!$O$5:$O$504,0))) | F24: =IF($B24="","",INDEX(Productos!$G$5:$G$504,MATCH($B24,Productos!$O$5:$O$504,0))) | G24: =IF($B24="","",INDEX(Productos!$N$5:$N$504,MATCH($B24,Productos!$O$5:$O$504,0))) | H24: =IF($B24="","",MAX(0,IF(N(INDEX(Productos!$H$5:$H$504,MATCH($B24,Productos!$O$5:$O$504,0)))>0,N(INDEX(Productos!$H$5:$H$504,MATCH($B24,Productos!$O$5:$O$504,0))),2*N(F24))-E24))
B25: =IF(9<=COUNTIF(Productos!$O$5:$O$504,">0"),9,"") | C25: =IF($B25="","",INDEX(Productos!$A$5:$A$504,MATCH($B25,Productos!$O$5:$O$504,0))) | D25: =IF($B25="","",INDEX(Productos!$B$5:$B$504,MATCH($B25,Productos!$O$5:$O$504,0))) | E25: =IF($B25="","",INDEX(Productos!$L$5:$L$504,MATCH($B25,Productos!$O$5:$O$504,0))) | F25: =IF($B25="","",INDEX(Productos!$G$5:$G$504,MATCH($B25,Productos!$O$5:$O$504,0))) | G25: =IF($B25="","",INDEX(Productos!$N$5:$N$504,MATCH($B25,Productos!$O$5:$O$504,0))) | H25: =IF($B25="","",MAX(0,IF(N(INDEX(Productos!$H$5:$H$504,MATCH($B25,Productos!$O$5:$O$504,0)))>0,N(INDEX(Productos!$H$5:$H$504,MATCH($B25,Productos!$O$5:$O$504,0))),2*N(F25))-E25))
B26: =IF(10<=COUNTIF(Productos!$O$5:$O$504,">0"),10,"") | C26: =IF($B26="","",INDEX(Productos!$A$5:$A$504,MATCH($B26,Productos!$O$5:$O$504,0))) | D26: =IF($B26="","",INDEX(Productos!$B$5:$B$504,MATCH($B26,Productos!$O$5:$O$504,0))) | E26: =IF($B26="","",INDEX(Productos!$L$5:$L$504,MATCH($B26,Productos!$O$5:$O$504,0))) | F26: =IF($B26="","",INDEX(Productos!$G$5:$G$504,MATCH($B26,Productos!$O$5:$O$504,0))) | G26: =IF($B26="","",INDEX(Productos!$N$5:$N$504,MATCH($B26,Productos!$O$5:$O$504,0))) | H26: =IF($B26="","",MAX(0,IF(N(INDEX(Productos!$H$5:$H$504,MATCH($B26,Productos!$O$5:$O$504,0)))>0,N(INDEX(Productos!$H$5:$H$504,MATCH($B26,Productos!$O$5:$O$504,0))),2*N(F26))-E26))
B27: =IF(11<=COUNTIF(Productos!$O$5:$O$504,">0"),11,"") | C27: =IF($B27="","",INDEX(Productos!$A$5:$A$504,MATCH($B27,Productos!$O$5:$O$504,0))) | D27: =IF($B27="","",INDEX(Productos!$B$5:$B$504,MATCH($B27,Productos!$O$5:$O$504,0))) | E27: =IF($B27="","",INDEX(Productos!$L$5:$L$504,MATCH($B27,Productos!$O$5:$O$504,0))) | F27: =IF($B27="","",INDEX(Productos!$G$5:$G$504,MATCH($B27,Productos!$O$5:$O$504,0))) | G27: =IF($B27="","",INDEX(Productos!$N$5:$N$504,MATCH($B27,Productos!$O$5:$O$504,0))) | H27: =IF($B27="","",MAX(0,IF(N(INDEX(Productos!$H$5:$H$504,MATCH($B27,Productos!$O$5:$O$504,0)))>0,N(INDEX(Productos!$H$5:$H$504,MATCH($B27,Productos!$O$5:$O$504,0))),2*N(F27))-E27))
B28: =IF(12<=COUNTIF(Productos!$O$5:$O$504,">0"),12,"") | C28: =IF($B28="","",INDEX(Productos!$A$5:$A$504,MATCH($B28,Productos!$O$5:$O$504,0))) | D28: =IF($B28="","",INDEX(Productos!$B$5:$B$504,MATCH($B28,Productos!$O$5:$O$504,0))) | E28: =IF($B28="","",INDEX(Productos!$L$5:$L$504,MATCH($B28,Productos!$O$5:$O$504,0))) | F28: =IF($B28="","",INDEX(Productos!$G$5:$G$504,MATCH($B28,Productos!$O$5:$O$504,0))) | G28: =IF($B28="","",INDEX(Productos!$N$5:$N$504,MATCH($B28,Productos!$O$5:$O$504,0))) | H28: =IF($B28="","",MAX(0,IF(N(INDEX(Productos!$H$5:$H$504,MATCH($B28,Productos!$O$5:$O$504,0)))>0,N(INDEX(Productos!$H$5:$H$504,MATCH($B28,Productos!$O$5:$O$504,0))),2*N(F28))-E28))
B29: =IF(13<=COUNTIF(Productos!$O$5:$O$504,">0"),13,"") | C29: =IF($B29="","",INDEX(Productos!$A$5:$A$504,MATCH($B29,Productos!$O$5:$O$504,0))) | D29: =IF($B29="","",INDEX(Productos!$B$5:$B$504,MATCH($B29,Productos!$O$5:$O$504,0))) | E29: =IF($B29="","",INDEX(Productos!$L$5:$L$504,MATCH($B29,Productos!$O$5:$O$504,0))) | F29: =IF($B29="","",INDEX(Productos!$G$5:$G$504,MATCH($B29,Productos!$O$5:$O$504,0))) | G29: =IF($B29="","",INDEX(Productos!$N$5:$N$504,MATCH($B29,Productos!$O$5:$O$504,0))) | H29: =IF($B29="","",MAX(0,IF(N(INDEX(Productos!$H$5:$H$504,MATCH($B29,Productos!$O$5:$O$504,0)))>0,N(INDEX(Productos!$H$5:$H$504,MATCH($B29,Productos!$O$5:$O$504,0))),2*N(F29))-E29))
B30: =IF(14<=COUNTIF(Productos!$O$5:$O$504,">0"),14,"") | C30: =IF($B30="","",INDEX(Productos!$A$5:$A$504,MATCH($B30,Productos!$O$5:$O$504,0))) | D30: =IF($B30="","",INDEX(Productos!$B$5:$B$504,MATCH($B30,Productos!$O$5:$O$504,0))) | E30: =IF($B30="","",INDEX(Productos!$L$5:$L$504,MATCH($B30,Productos!$O$5:$O$504,0))) | F30: =IF($B30="","",INDEX(Productos!$G$5:$G$504,MATCH($B30,Productos!$O$5:$O$504,0))) | G30: =IF($B30="","",INDEX(Productos!$N$5:$N$504,MATCH($B30,Productos!$O$5:$O$504,0))) | H30: =IF($B30="","",MAX(0,IF(N(INDEX(Productos!$H$5:$H$504,MATCH($B30,Productos!$O$5:$O$504,0)))>0,N(INDEX(Productos!$H$5:$H$504,MATCH($B30,Productos!$O$5:$O$504,0))),2*N(F30))-E30))
B31: =IF(15<=COUNTIF(Productos!$O$5:$O$504,">0"),15,"") | C31: =IF($B31="","",INDEX(Productos!$A$5:$A$504,MATCH($B31,Productos!$O$5:$O$504,0))) | D31: =IF($B31="","",INDEX(Productos!$B$5:$B$504,MATCH($B31,Productos!$O$5:$O$504,0))) | E31: =IF($B31="","",INDEX(Productos!$L$5:$L$504,MATCH($B31,Productos!$O$5:$O$504,0))) | F31: =IF($B31="","",INDEX(Productos!$G$5:$G$504,MATCH($B31,Productos!$O$5:$O$504,0))) | G31: =IF($B31="","",INDEX(Productos!$N$5:$N$504,MATCH($B31,Productos!$O$5:$O$504,0))) | H31: =IF($B31="","",MAX(0,IF(N(INDEX(Productos!$H$5:$H$504,MATCH($B31,Productos!$O$5:$O$504,0)))>0,N(INDEX(Productos!$H$5:$H$504,MATCH($B31,Productos!$O$5:$O$504,0))),2*N(F31))-E31))
B32: =IF(16<=COUNTIF(Productos!$O$5:$O$504,">0"),16,"") | C32: =IF($B32="","",INDEX(Productos!$A$5:$A$504,MATCH($B32,Productos!$O$5:$O$504,0))) | D32: =IF($B32="","",INDEX(Productos!$B$5:$B$504,MATCH($B32,Productos!$O$5:$O$504,0))) | E32: =IF($B32="","",INDEX(Productos!$L$5:$L$504,MATCH($B32,Productos!$O$5:$O$504,0))) | F32: =IF($B32="","",INDEX(Productos!$G$5:$G$504,MATCH($B32,Productos!$O$5:$O$504,0))) | G32: =IF($B32="","",INDEX(Productos!$N$5:$N$504,MATCH($B32,Productos!$O$5:$O$504,0))) | H32: =IF($B32="","",MAX(0,IF(N(INDEX(Productos!$H$5:$H$504,MATCH($B32,Productos!$O$5:$O$504,0)))>0,N(INDEX(Productos!$H$5:$H$504,MATCH($B32,Productos!$O$5:$O$504,0))),2*N(F32))-E32))
B33: =IF(17<=COUNTIF(Productos!$O$5:$O$504,">0"),17,"") | C33: =IF($B33="","",INDEX(Productos!$A$5:$A$504,MATCH($B33,Productos!$O$5:$O$504,0))) | D33: =IF($B33="","",INDEX(Productos!$B$5:$B$504,MATCH($B33,Productos!$O$5:$O$504,0))) | E33: =IF($B33="","",INDEX(Productos!$L$5:$L$504,MATCH($B33,Productos!$O$5:$O$504,0))) | F33: =IF($B33="","",INDEX(Productos!$G$5:$G$504,MATCH($B33,Productos!$O$5:$O$504,0))) | G33: =IF($B33="","",INDEX(Productos!$N$5:$N$504,MATCH($B33,Productos!$O$5:$O$504,0))) | H33: =IF($B33="","",MAX(0,IF(N(INDEX(Productos!$H$5:$H$504,MATCH($B33,Productos!$O$5:$O$504,0)))>0,N(INDEX(Productos!$H$5:$H$504,MATCH($B33,Productos!$O$5:$O$504,0))),2*N(F33))-E33))
B34: =IF(18<=COUNTIF(Productos!$O$5:$O$504,">0"),18,"") | C34: =IF($B34="","",INDEX(Productos!$A$5:$A$504,MATCH($B34,Productos!$O$5:$O$504,0))) | D34: =IF($B34="","",INDEX(Productos!$B$5:$B$504,MATCH($B34,Productos!$O$5:$O$504,0))) | E34: =IF($B34="","",INDEX(Productos!$L$5:$L$504,MATCH($B34,Productos!$O$5:$O$504,0))) | F34: =IF($B34="","",INDEX(Productos!$G$5:$G$504,MATCH($B34,Productos!$O$5:$O$504,0))) | G34: =IF($B34="","",INDEX(Productos!$N$5:$N$504,MATCH($B34,Productos!$O$5:$O$504,0))) | H34: =IF($B34="","",MAX(0,IF(N(INDEX(Productos!$H$5:$H$504,MATCH($B34,Productos!$O$5:$O$504,0)))>0,N(INDEX(Productos!$H$5:$H$504,MATCH($B34,Productos!$O$5:$O$504,0))),2*N(F34))-E34))
B35: =IF(19<=COUNTIF(Productos!$O$5:$O$504,">0"),19,"") | C35: =IF($B35="","",INDEX(Productos!$A$5:$A$504,MATCH($B35,Productos!$O$5:$O$504,0))) | D35: =IF($B35="","",INDEX(Productos!$B$5:$B$504,MATCH($B35,Productos!$O$5:$O$504,0))) | E35: =IF($B35="","",INDEX(Productos!$L$5:$L$504,MATCH($B35,Productos!$O$5:$O$504,0))) | F35: =IF($B35="","",INDEX(Productos!$G$5:$G$504,MATCH($B35,Productos!$O$5:$O$504,0))) | G35: =IF($B35="","",INDEX(Productos!$N$5:$N$504,MATCH($B35,Productos!$O$5:$O$504,0))) | H35: =IF($B35="","",MAX(0,IF(N(INDEX(Productos!$H$5:$H$504,MATCH($B35,Productos!$O$5:$O$504,0)))>0,N(INDEX(Productos!$H$5:$H$504,MATCH($B35,Productos!$O$5:$O$504,0))),2*N(F35))-E35))
B36: =IF(20<=COUNTIF(Productos!$O$5:$O$504,">0"),20,"") | C36: =IF($B36="","",INDEX(Productos!$A$5:$A$504,MATCH($B36,Productos!$O$5:$O$504,0))) | D36: =IF($B36="","",INDEX(Productos!$B$5:$B$504,MATCH($B36,Productos!$O$5:$O$504,0))) | E36: =IF($B36="","",INDEX(Productos!$L$5:$L$504,MATCH($B36,Productos!$O$5:$O$504,0))) | F36: =IF($B36="","",INDEX(Productos!$G$5:$G$504,MATCH($B36,Productos!$O$5:$O$504,0))) | G36: =IF($B36="","",INDEX(Productos!$N$5:$N$504,MATCH($B36,Productos!$O$5:$O$504,0))) | H36: =IF($B36="","",MAX(0,IF(N(INDEX(Productos!$H$5:$H$504,MATCH($B36,Productos!$O$5:$O$504,0)))>0,N(INDEX(Productos!$H$5:$H$504,MATCH($B36,Productos!$O$5:$O$504,0))),2*N(F36))-E36))
B37: =IF(21<=COUNTIF(Productos!$O$5:$O$504,">0"),21,"") | C37: =IF($B37="","",INDEX(Productos!$A$5:$A$504,MATCH($B37,Productos!$O$5:$O$504,0))) | D37: =IF($B37="","",INDEX(Productos!$B$5:$B$504,MATCH($B37,Productos!$O$5:$O$504,0))) | E37: =IF($B37="","",INDEX(Productos!$L$5:$L$504,MATCH($B37,Productos!$O$5:$O$504,0))) | F37: =IF($B37="","",INDEX(Productos!$G$5:$G$504,MATCH($B37,Productos!$O$5:$O$504,0))) | G37: =IF($B37="","",INDEX(Productos!$N$5:$N$504,MATCH($B37,Productos!$O$5:$O$504,0))) | H37: =IF($B37="","",MAX(0,IF(N(INDEX(Productos!$H$5:$H$504,MATCH($B37,Productos!$O$5:$O$504,0)))>0,N(INDEX(Productos!$H$5:$H$504,MATCH($B37,Productos!$O$5:$O$504,0))),2*N(F37))-E37))
B38: =IF(22<=COUNTIF(Productos!$O$5:$O$504,">0"),22,"") | C38: =IF($B38="","",INDEX(Productos!$A$5:$A$504,MATCH($B38,Productos!$O$5:$O$504,0))) | D38: =IF($B38="","",INDEX(Productos!$B$5:$B$504,MATCH($B38,Productos!$O$5:$O$504,0))) | E38: =IF($B38="","",INDEX(Productos!$L$5:$L$504,MATCH($B38,Productos!$O$5:$O$504,0))) | F38: =IF($B38="","",INDEX(Productos!$G$5:$G$504,MATCH($B38,Productos!$O$5:$O$504,0))) | G38: =IF($B38="","",INDEX(Productos!$N$5:$N$504,MATCH($B38,Productos!$O$5:$O$504,0))) | H38: =IF($B38="","",MAX(0,IF(N(INDEX(Productos!$H$5:$H$504,MATCH($B38,Productos!$O$5:$O$504,0)))>0,N(INDEX(Productos!$H$5:$H$504,MATCH($B38,Productos!$O$5:$O$504,0))),2*N(F38))-E38))
B39: =IF(23<=COUNTIF(Productos!$O$5:$O$504,">0"),23,"") | C39: =IF($B39="","",INDEX(Productos!$A$5:$A$504,MATCH($B39,Productos!$O$5:$O$504,0))) | D39: =IF($B39="","",INDEX(Productos!$B$5:$B$504,MATCH($B39,Productos!$O$5:$O$504,0))) | E39: =IF($B39="","",INDEX(Productos!$L$5:$L$504,MATCH($B39,Productos!$O$5:$O$504,0))) | F39: =IF($B39="","",INDEX(Productos!$G$5:$G$504,MATCH($B39,Productos!$O$5:$O$504,0))) | G39: =IF($B39="","",INDEX(Productos!$N$5:$N$504,MATCH($B39,Productos!$O$5:$O$504,0))) | H39: =IF($B39="","",MAX(0,IF(N(INDEX(Productos!$H$5:$H$504,MATCH($B39,Productos!$O$5:$O$504,0)))>0,N(INDEX(Productos!$H$5:$H$504,MATCH($B39,Productos!$O$5:$O$504,0))),2*N(F39))-E39))
B40: =IF(24<=COUNTIF(Productos!$O$5:$O$504,">0"),24,"") | C40: =IF($B40="","",INDEX(Productos!$A$5:$A$504,MATCH($B40,Productos!$O$5:$O$504,0))) | D40: =IF($B40="","",INDEX(Productos!$B$5:$B$504,MATCH($B40,Productos!$O$5:$O$504,0))) | E40: =IF($B40="","",INDEX(Productos!$L$5:$L$504,MATCH($B40,Productos!$O$5:$O$504,0))) | F40: =IF($B40="","",INDEX(Productos!$G$5:$G$504,MATCH($B40,Productos!$O$5:$O$504,0))) | G40: =IF($B40="","",INDEX(Productos!$N$5:$N$504,MATCH($B40,Productos!$O$5:$O$504,0))) | H40: =IF($B40="","",MAX(0,IF(N(INDEX(Productos!$H$5:$H$504,MATCH($B40,Productos!$O$5:$O$504,0)))>0,N(INDEX(Productos!$H$5:$H$504,MATCH($B40,Productos!$O$5:$O$504,0))),2*N(F40))-E40))
B41: =IF(25<=COUNTIF(Productos!$O$5:$O$504,">0"),25,"") | C41: =IF($B41="","",INDEX(Productos!$A$5:$A$504,MATCH($B41,Productos!$O$5:$O$504,0))) | D41: =IF($B41="","",INDEX(Productos!$B$5:$B$504,MATCH($B41,Productos!$O$5:$O$504,0))) | E41: =IF($B41="","",INDEX(Productos!$L$5:$L$504,MATCH($B41,Productos!$O$5:$O$504,0))) | F41: =IF($B41="","",INDEX(Productos!$G$5:$G$504,MATCH($B41,Productos!$O$5:$O$504,0))) | G41: =IF($B41="","",INDEX(Productos!$N$5:$N$504,MATCH($B41,Productos!$O$5:$O$504,0))) | H41: =IF($B41="","",MAX(0,IF(N(INDEX(Productos!$H$5:$H$504,MATCH($B41,Productos!$O$5:$O$504,0)))>0,N(INDEX(Productos!$H$5:$H$504,MATCH($B41,Productos!$O$5:$O$504,0))),2*N(F41))-E41))
B42: Muestra hasta 25 artículos. Si tienes más pendientes, filtra la columna Estado en la hoja Productos.

Sheet Productos
A1: Catálogo y existencias
A2: Captura tus artículos en las columnas amarillas. Las grises se calculan solas con los movimientos.
A4: Clave | B4: Descripción | C4: Categoría | D4: Unidad | E4: Ubicación | F4: Costo unitario | G4: Stock mínimo | H4: Stock máximo | I4: Existencia inicial | J4: Entradas | K4: Salidas | L4: Existencia actual | M4: Valor del inventario | N4: Estado | O4: n_compra
A5: P-001 | B5: Cemento gris 50 kg | C5: Materiales | D5: Bulto | E5: Bodega A | F5: 215 | G5: 40 | H5: 120 | I5: 80 | J5: =IF($A5="","",SUMIFS(Movimientos!$F$5:$F$3004,Movimientos!$C$5:$C$3004,$A5,Movimientos!$B$5:$B$3004,"Entrada")) -> 60 | K5: =IF($A5="","",SUMIFS(Movimientos!$F$5:$F$3004,Movimientos!$C$5:$C$3004,$A5,Movimientos!$B$5:$B$3004,"Salida")) -> 85 | L5: =IF($A5="","",N(I5)+J5-K5) -> 55 | M5: =IF($A5="","",L5*N(F5)) -> 11825 | N5: =IF($A5="","",IF(L5<=0,"Agotado",IF(AND(N(G5)>0,L5<=G5),"Reordenar","OK"))) -> OK | O5: =IF(OR(N5="Reordenar",N5="Agotado"),COUNTIF($N$5:N5,"Reordenar")+COUNTIF($N$5:N5,"Agotado"),"")
A6: P-002 | B6: Varilla corrugada 3/8" | C6: Acero | D6: Pieza | E6: Patio | F6: 168 | G6: 100 | H6: 300 | I6: 150 | J6: =IF($A6="","",SUMIFS(Movimientos!$F$5:$F$3004,Movimientos!$C$5:$C$3004,$A6,Movimientos!$B$5:$B$3004,"Entrada")) -> 120 | K6: =IF($A6="","",SUMIFS(Movimientos!$F$5:$F$3004,Movimientos!$C$5:$C$3004,$A6,Movimientos!$B$5:$B$3004,"Salida")) -> 210 | L6: =IF($A6="","",N(I6)+J6-K6) -> 60 | M6: =IF($A6="","",L6*N(F6)) -> 10080 | N6: =IF($A6="","",IF(L6<=0,"Agotado",IF(AND(N(G6)>0,L6<=G6),"Reordenar","OK"))) -> Reordenar | O6: =IF(OR(N6="Reordenar",N6="Agotado"),COUNTIF($N$5:N6,"Reordenar")+COUNTIF($N$5:N6,"Agotado"),"") -> 1
A7: P-003 | B7: Block de concreto 15x20x40 | C7: Materiales | D7: Pieza | E7: Patio | F7: 14.5 | G7: 500 | H7: 2000 | I7: 1200 | J7: =IF($A7="","",SUMIFS(Movimientos!$F$5:$F$3004,Movimientos!$C$5:$C$3004,$A7,Movimientos!$B$5:$B$3004,"Entrada")) -> 0 | K7: =IF($A7="","",SUMIFS(Movimientos!$F$5:$F$3004,Movimientos!$C$5:$C$3004,$A7,Movimientos!$B$5:$B$3004,"Salida")) -> 780 | L7: =IF($A7="","",N(I7)+J7-K7) -> 420 | M7: =IF($A7="","",L7*N(F7)) -> 6090 | N7: =IF($A7="","",IF(L7<=0,"Agotado",IF(AND(N(G7)>0,L7<=G7),"Reordenar","OK"))) -> Reordenar | O7: =IF(OR(N7="Reordenar",N7="Agotado"),COUNTIF($N$5:N7,"Reordenar")+COUNTIF($N$5:N7,"Agotado"),"") -> 2
A8: P-004 | B8: Tubo PVC hidráulico 1/2" | C8: Plomería | D8: Tramo | E8: Bodega B | F8: 62 | G8: 30 | H8: 100 | I8: 45 | J8: =IF($A8="","",SUMIFS(Movimientos!$F$5:$F$3004,Movimientos!$C$5:$C$3004,$A8,Movimientos!$B$5:$B$3004,"Entrada")) -> 40 | K8: =IF($A8="","",SUMIFS(Movimientos!$F$5:$F$3004,Movimientos!$C$5:$C$3004,$A8,Movimientos!$B$5:$B$3004,"Salida")) -> 52 | L8: =IF($A8="","",N(I8)+J8-K8) -> 33 | M8: =IF($A8="","",L8*N(F8)) -> 2046 | N8: =IF($A8="","",IF(L8<=0,"Agotado",IF(AND(N(G8)>0,L8<=G8),"Reordenar","OK"))) -> OK | O8: =IF(OR(N8="Reordenar",N8="Agotado"),COUNTIF($N$5:N8,"Reordenar")+COUNTIF($N$5:N8,"Agotado"),"")
A9: P-005 | B9: Pintura vinílica blanca 19 L | C9: Pinturas | D9: Cubeta | E9: Bodega B | F9: 1150 | G9: 5 | H9: 20 | I9: 8 | J9: =IF($A9="","",SUMIFS(Movimientos!$F$5:$F$3004,Movimientos!$C$5:$C$3004,$A9,Movimientos!$B$5:$B$3004,"Entrada")) -> 0 | K9: =IF($A9="","",SUMIFS(Movimientos!$F$5:$F$3004,Movimientos!$C$5:$C$3004,$A9,Movimientos!$B$5:$B$3004,"Salida")) -> 4 | L9: =IF($A9="","",N(I9)+J9-K9) -> 4 | M9: =IF($A9="","",L9*N(F9)) -> 4600 | N9: =IF($A9="","",IF(L9<=0,"Agotado",IF(AND(N(G9)>0,L9<=G9),"Reordenar","OK"))) -> Reordenar | O9: =IF(OR(N9="Reordenar",N9="Agotado"),COUNTIF($N$5:N9,"Reordenar")+COUNTIF($N$5:N9,"Agotado"),"") -> 3
A10: P-006 | B10: Alambre recocido | C10: Acero | D10: Kg | E10: Bodega A | F10: 38 | G10: 50 | H10: 200 | I10: 60 | J10: =IF($A10="","",SUMIFS(Movimientos!$F$5:$F$3004,Movimientos!$C$5:$C$3004,$A10,Movimientos!$B$5:$B$3004,"Entrada")) -> 0 | K10: =IF($A10="","",SUMIFS(Movimientos!$F$5:$F$3004,Movimientos!$C$5:$C$3004,$A10,Movimientos!$B$5:$B$3004,"Salida")) -> 25 | L10: =IF($A10="","",N(I10)+J10-K10) -> 35 | M10: =IF($A10="","",L10*N(F10)) -> 1330 | N10: =IF($A10="","",IF(L10<=0,"Agotado",IF(AND(N(G10)>0,L10<=G10),"Reordenar","OK"))) -> Reordenar | O10: =IF(OR(N10="Reordenar",N10="Agotado"),COUNTIF($N$5:N10,"Reordenar")+COUNTIF($N$5:N10,"Agotado"),"") -> 4
A11: P-007 | B11: Cable THW calibre 12 | C11: Eléctrico | D11: Rollo 100 m | E11: Bodega B | F11: 980 | G11: 4 | H11: 12 | I11: 3 | J11: =IF($A11="","",SUMIFS(Movimientos!$F$5:$F$3004,Movimientos!$C$5:$C$3004,$A11,Movimientos!$B$5:$B$3004,"Entrada")) -> 0 | K11: =IF($A11="","",SUMIFS(Movimientos!$F$5:$F$3004,Movimientos!$C$5:$C$3004,$A11,Movimientos!$B$5:$B$3004,"Salida")) -> 3 | L11: =IF($A11="","",N(I11)+J11-K11) -> 0 | M11: =IF($A11="","",L11*N(F11)) -> 0 | N11: =IF($A11="","",IF(L11<=0,"Agotado",IF(AND(N(G11)>0,L11<=G11),"Reordenar","OK"))) -> Agotado | O11: =IF(OR(N11="Reordenar",N11="Agotado"),COUNTIF($N$5:N11,"Reordenar")+COUNTIF($N$5:N11,"Agotado"),"") -> 5
A12: P-008 | B12: Tornillo para tablaroca 1" | C12: Ferretería | D12: Caja 1000 | E12: Bodega A | F12: 145 | G12: 10 | H12: 40 | I12: 22 | J12: =IF($A12="","",SUMIFS(Movimientos!$F$5:$F$3004,Movimientos!$C$5:$C$3004,$A12,Movimientos!$B$5:$B$3004,"Entrada")) -> 10 | K12: =IF($A12="","",SUMIFS(Movimientos!$F$5:$F$3004,Movimientos!$C$5:$C$3004,$A12,Movimientos!$B$5:$B$3004,"Salida")) -> 14 | L12: =IF($A12="","",N(I12)+J12-K12) -> 18 | M12: =IF($A12="","",L12*N(F12)) -> 2610 | N12: =IF($A12="","",IF(L12<=0,"Agotado",IF(AND(N(G12)>0,L12<=G12),"Reordenar","OK"))) -> OK | O12: =IF(OR(N12="Reordenar",N12="Agotado"),COUNTIF($N$5:N12,"Reordenar")+COUNTIF($N$5:N12,"Agotado"),"")
J13: =IF($A13="","",SUMIFS(Movimientos!$F$5:$F$3004,Movimientos!$C$5:$C$3004,$A13,Movimientos!$B$5:$B$3004,"Entrada")) | K13: =IF($A13="","",SUMIFS(Movimientos!$F$5:$F$3004,Movimientos!$C$5:$C$3004,$A13,Movimientos!$B$5:$B$3004,"Salida")) | L13: =IF($A13="","",N(I13)+J13-K13) | M13: =IF($A13="","",L13*N(F13)) | N13: =IF($A13="","",IF(L13<=0,"Agotado",IF(AND(N(G13)>0,L13<=G13),"Reordenar","OK"))) | O13: =IF(OR(N13="Reordenar",N13="Agotado"),COUNTIF($N$5:N13,"Reordenar")+COUNTIF($N$5:N13,"Agotado"),"")
J14: =IF($A14="","",SUMIFS(Movimientos!$F$5:$F$3004,Movimientos!$C$5:$C$3004,$A14,Movimientos!$B$5:$B$3004,"Entrada")) | K14: =IF($A14="","",SUMIFS(Movimientos!$F$5:$F$3004,Movimientos!$C$5:$C$3004,$A14,Movimientos!$B$5:$B$3004,"Salida")) | L14: =IF($A14="","",N(I14)+J14-K14) | M14: =IF($A14="","",L14*N(F14)) | N14: =IF($A14="","",IF(L14<=0,"Agotado",IF(AND(N(G14)>0,L14<=G14),"Reordenar","OK"))) | O14: =IF(OR(N14="Reordenar",N14="Agotado"),COUNTIF($N$5:N14,"Reordenar")+COUNTIF($N$5:N14,"Agotado"),"")
J15: =IF($A15="","",SUMIFS(Movimientos!$F$5:$F$3004,Movimientos!$C$5:$C$3004,$A15,Movimientos!$B$5:$B$3004,"Entrada")) | K15: =IF($A15="","",SUMIFS(Movimientos!$F$5:$F$3004,Movimientos!$C$5:$C$3004,$A15,Movimientos!$B$5:$B$3004,"Salida")) | L15: =IF($A15="","",N(I15)+J15-K15) | M15: =IF($A15="","",L15*N(F15)) | N15: =IF($A15="","",IF(L15<=0,"Agotado",IF(AND(N(G15)>0,L15<=G15),"Reordenar","OK"))) | O15: =IF(OR(N15="Reordenar",N15="Agotado"),COUNTIF($N$5:N15,"Reordenar")+COUNTIF($N$5:N15,"Agotado"),"")
J16: =IF($A16="","",SUMIFS(Movimientos!$F$5:$F$3004,Movimientos!$C$5:$C$3004,$A16,Movimientos!$B$5:$B$3004,"Entrada")) | K16: =IF($A16="","",SUMIFS(Movimientos!$F$5:$F$3004,Movimientos!$C$5:$C$3004,$A16,Movimientos!$B$5:$B$3004,"Salida")) | L16: =IF($A16="","",N(I16)+J16-K16) | M16: =IF($A16="","",L16*N(F16)) | N16: =IF($A16="","",IF(L16<=0,"Agotado",IF(AND(N(G16)>0,L16<=G16),"Reordenar","OK"))) | O16: =IF(OR(N16="Reordenar",N16="Agotado"),COUNTIF($N$5:N16,"Reordenar")+COUNTIF($N$5:N16,"Agotado"),"")
J17: =IF($A17="","",SUMIFS(Movimientos!$F$5:$F$3004,Movimientos!$C$5:$C$3004,$A17,Movimientos!$B$5:$B$3004,"Entrada")) | K17: =IF($A17="","",SUMIFS(Movimientos!$F$5:$F$3004,Movimientos!$C$5:$C$3004,$A17,Movimientos!$B$5:$B$3004,"Salida")) | L17: =IF($A17="","",N(I17)+J17-K17) | M17: =IF($A17="","",L17*N(F17)) | N17: =IF($A17="","",IF(L17<=0,"Agotado",IF(AND(N(G17)>0,L17<=G17),"Reordenar","OK"))) | O17: =IF(OR(N17="Reordenar",N17="Agotado"),COUNTIF($N$5:N17,"Reordenar")+COUNTIF($N$5:N17,"Agotado"),"")
J18: =IF($A18="","",SUMIFS(Movimientos!$F$5:$F$3004,Movimientos!$C$5:$C$3004,$A18,Movimientos!$B$5:$B$3004,"Entrada")) | K18: =IF($A18="","",SUMIFS(Movimientos!$F$5:$F$3004,Movimientos!$C$5:$C$3004,$A18,Movimientos!$B$5:$B$3004,"Salida")) | L18: =IF($A18="","",N(I18)+J18-K18) | M18: =IF($A18="","",L18*N(F18)) | N18: =IF($A18="","",IF(L18<=0,"Agotado",IF(AND(N(G18)>0,L18<=G18),"Reordenar","OK"))) | O18: =IF(OR(N18="Reordenar",N18="Agotado"),COUNTIF($N$5:N18,"Reordenar")+COUNTIF($N$5:N18,"Agotado"),"")
J19: =IF($A19="","",SUMIFS(Movimientos!$F$5:$F$3004,Movimientos!$C$5:$C$3004,$A19,Movimientos!$B$5:$B$3004,"Entrada")) | K19: =IF($A19="","",SUMIFS(Movimientos!$F$5:$F$3004,Movimientos!$C$5:$C$3004,$A19,Movimientos!$B$5:$B$3004,"Salida")) | L19: =IF($A19="","",N(I19)+J19-K19) | M19: =IF($A19="","",L19*N(F19)) | N19: =IF($A19="","",IF(L19<=0,"Agotado",IF(AND(N(G19)>0,L19<=G19),"Reordenar","OK"))) | O19: =IF(OR(N19="Reordenar",N19="Agotado"),COUNTIF($N$5:N19,"Reordenar")+COUNTIF($N$5:N19,"Agotado"),"")
J20: =IF($A20="","",SUMIFS(Movimientos!$F$5:$F$3004,Movimientos!$C$5:$C$3004,$A20,Movimientos!$B$5:$B$3004,"Entrada")) | K20: =IF($A20="","",SUMIFS(Movimientos!$F$5:$F$3004,Movimientos!$C$5:$C$3004,$A20,Movimientos!$B$5:$B$3004,"Salida")) | L20: =IF($A20="","",N(I20)+J20-K20) | M20: =IF($A20="","",L20*N(F20)) | N20: =IF($A20="","",IF(L20<=0,"Agotado",IF(AND(N(G20)>0,L20<=G20),"Reordenar","OK"))) | O20: =IF(OR(N20="Reordenar",N20="Agotado"),COUNTIF($N$5:N20,"Reordenar")+COUNTIF($N$5:N20,"Agotado"),"")
J21: =IF($A21="","",SUMIFS(Movimientos!$F$5:$F$3004,Movimientos!$C$5:$C$3004,$A21,Movimientos!$B$5:$B$3004,"Entrada")) | K21: =IF($A21="","",SUMIFS(Movimientos!$F$5:$F$3004,Movimientos!$C$5:$C$3004,$A21,Movimientos!$B$5:$B$3004,"Salida")) | L21: =IF($A21="","",N(I21)+J21-K21) | M21: =IF($A21="","",L21*N(F21)) | N21: =IF($A21="","",IF(L21<=0,"Agotado",IF(AND(N(G21)>0,L21<=G21),"Reordenar","OK"))) | O21: =IF(OR(N21="Reordenar",N21="Agotado"),COUNTIF($N$5:N21,"Reordenar")+COUNTIF($N$5:N21,"Agotado"),"")
J22: =IF($A22="","",SUMIFS(Movimientos!$F$5:$F$3004,Movimientos!$C$5:$C$3004,$A22,Movimientos!$B$5:$B$3004,"Entrada")) | K22: =IF($A22="","",SUMIFS(Movimientos!$F$5:$F$3004,Movimientos!$C$5:$C$3004,$A22,Movimientos!$B$5:$B$3004,"Salida")) | L22: =IF($A22="","",N(I22)+J22-K22) | M22: =IF($A22="","",L22*N(F22)) | N22: =IF($A22="","",IF(L22<=0,"Agotado",IF(AND(N(G22)>0,L22<=G22),"Reordenar","OK"))) | O22: =IF(OR(N22="Reordenar",N22="Agotado"),COUNTIF($N$5:N22,"Reordenar")+COUNTIF($N$5:N22,"Agotado"),"")
J23: =IF($A23="","",SUMIFS(Movimientos!$F$5:$F$3004,Movimientos!$C$5:$C$3004,$A23,Movimientos!$B$5:$B$3004,"Entrada")) | K23: =IF($A23="","",SUMIFS(Movimientos!$F$5:$F$3004,Movimientos!$C$5:$C$3004,$A23,Movimientos!$B$5:$B$3004,"Salida")) | L23: =IF($A23="","",N(I23)+J23-K23) | M23: =IF($A23="","",L23*N(F23)) | N23: =IF($A23="","",IF(L23<=0,"Agotado",IF(AND(N(G23)>0,L23<=G23),"Reordenar","OK"))) | O23: =IF(OR(N23="Reordenar",N23="Agotado"),COUNTIF($N$5:N23,"Reordenar")+COUNTIF($N$5:N23,"Agotado"),"")
J24: =IF($A24="","",SUMIFS(Movimientos!$F$5:$F$3004,Movimientos!$C$5:$C$3004,$A24,Movimientos!$B$5:$B$3004,"Entrada")) | K24: =IF($A24="","",SUMIFS(Movimientos!$F$5:$F$3004,Movimientos!$C$5:$C$3004,$A24,Movimientos!$B$5:$B$3004,"Salida")) | L24: =IF($A24="","",N(I24)+J24-K24) | M24: =IF($A24="","",L24*N(F24)) | N24: =IF($A24="","",IF(L24<=0,"Agotado",IF(AND(N(G24)>0,L24<=G24),"Reordenar","OK"))) | O24: =IF(OR(N24="Reordenar",N24="Agotado"),COUNTIF($N$5:N24,"Reordenar")+COUNTIF($N$5:N24,"Agotado"),"")
... J504: =IF($A504="","",SUMIFS(Movimientos!$F$5:$F$3004,Movimientos!$C$5:$C$3004,$A504,Movimientos!$B$5:$B$3004,"Entrada")) | K504: =IF($A504="","",SUMIFS(Movimientos!$F$5:$F$3004,Movimientos!$C$5:$C$3004,$A504,Movimientos!$B$5:$B$3004,"Salida")) | L504: =IF($A504="","",N(I504)+J504-K504) | M504: =IF($A504="","",L504*N(F504)) | N504: =IF($A504="","",IF(L504<=0,"Agotado",IF(AND(N(G504)>0,L504<=G504),"Reordenar","OK"))) | O504: =IF(OR(N504="Reordenar",N504="Agotado"),COUNTIF($N$5:N504,"Reordenar")+COUNTIF($N$5:N504,"Agotado"),"")

Sheet Movimientos
A1: Entradas y salidas
A2: Una fila por movimiento, en orden de fecha. Tipo: Entrada o Salida. La clave debe existir en Productos.
A4: Fecha | B4: Tipo | C4: Clave | D4: Descripción | E4: Unidad | F4: Cantidad | G4: Costo unitario | H4: Importe | I4: Existencia después | J4: Referencia | K4: Responsable | L4: Notas | M4: n_kardex
A5: 46296 | B5: Entrada | C5: P-001 | D5: =IF($C5="","",IFERROR(INDEX(Productos!$B$5:$B$504,MATCH($C5,Productos!$A$5:$A$504,0)),"Clave no existe")) -> Cemento gris 50 kg | E5: =IF($C5="","",IFERROR(INDEX(Productos!$D$5:$D$504,MATCH($C5,Productos!$A$5:$A$504,0)),"")) -> Bulto | F5: 60 | G5: =IF($C5="","",IFERROR(INDEX(Productos!$F$5:$F$504,MATCH($C5,Productos!$A$5:$A$504,0)),0)) -> 215 | H5: =IF(OR($C5="",$F5=""),"",F5*G5) -> 12900 | I5: =IF(OR($C5="",$F5=""),"",IFERROR(INDEX(Productos!$I$5:$I$504,MATCH($C5,Productos!$A$5:$A$504,0)),0)+SUMIFS($F$5:$F5,$C$5:$C5,$C5,$B$5:$B5,"Entrada")-SUMIFS($F$5:$F5,$C$5:$C5,$C5,$B$5:$B5,"Salida")) -> 140 | J5: Factura A-1182 | K5: Almacén | M5: =IF(AND($C5<>"",$C5=Kardex!$C$4),COUNTIF($C$5:$C5,Kardex!$C$4),"") -> 1
A6: 46297 | B6: Salida | C6: P-001 | D6: =IF($C6="","",IFERROR(INDEX(Productos!$B$5:$B$504,MATCH($C6,Productos!$A$5:$A$504,0)),"Clave no existe")) -> Cemento gris 50 kg | E6: =IF($C6="","",IFERROR(INDEX(Productos!$D$5:$D$504,MATCH($C6,Productos!$A$5:$A$504,0)),"")) -> Bulto | F6: 35 | G6: =IF($C6="","",IFERROR(INDEX(Productos!$F$5:$F$504,MATCH($C6,Productos!$A$5:$A$504,0)),0)) -> 215 | H6: =IF(OR($C6="",$F6=""),"",F6*G6) -> 7525 | I6: =IF(OR($C6="",$F6=""),"",IFERROR(INDEX(Productos!$I$5:$I$504,MATCH($C6,Productos!$A$5:$A$504,0)),0)+SUMIFS($F$5:$F6,$C$5:$C6,$C6,$B$5:$B6,"Entrada")-SUMIFS($F$5:$F6,$C$5:$C6,$C6,$B$5:$B6,"Salida")) -> 105 | J6: Pedido 0451 | K6: Ventas | M6: =IF(AND($C6<>"",$C6=Kardex!$C$4),COUNTIF($C$5:$C6,Kardex!$C$4),"") -> 2
A7: 46298 | B7: Salida | C7: P-003 | D7: =IF($C7="","",IFERROR(INDEX(Productos!$B$5:$B$504,MATCH($C7,Productos!$A$5:$A$504,0)),"Clave no existe")) -> Block de concreto 15x20x40 | E7: =IF($C7="","",IFERROR(INDEX(Productos!$D$5:$D$504,MATCH($C7,Productos!$A$5:$A$504,0)),"")) -> Pieza | F7: 400 | G7: =IF($C7="","",IFERROR(INDEX(Productos!$F$5:$F$504,MATCH($C7,Productos!$A$5:$A$504,0)),0)) -> 14.5 | H7: =IF(OR($C7="",$F7=""),"",F7*G7) -> 5800 | I7: =IF(OR($C7="",$F7=""),"",IFERROR(INDEX(Productos!$I$5:$I$504,MATCH($C7,Productos!$A$5:$A$504,0)),0)+SUMIFS($F$5:$F7,$C$5:$C7,$C7,$B$5:$B7,"Entrada")-SUMIFS($F$5:$F7,$C$5:$C7,$C7,$B$5:$B7,"Salida")) -> 800 | J7: Pedido 0452 | K7: Ventas | M7: =IF(AND($C7<>"",$C7=Kardex!$C$4),COUNTIF($C$5:$C7,Kardex!$C$4),"")
A8: 46301 | B8: Entrada | C8: P-002 | D8: =IF($C8="","",IFERROR(INDEX(Productos!$B$5:$B$504,MATCH($C8,Productos!$A$5:$A$504,0)),"Clave no existe")) -> Varilla corrugada 3/8" | E8: =IF($C8="","",IFERROR(INDEX(Productos!$D$5:$D$504,MATCH($C8,Productos!$A$5:$A$504,0)),"")) -> Pieza | F8: 120 | G8: =IF($C8="","",IFERROR(INDEX(Productos!$F$5:$F$504,MATCH($C8,Productos!$A$5:$A$504,0)),0)) -> 168 | H8: =IF(OR($C8="",$F8=""),"",F8*G8) -> 20160 | I8: =IF(OR($C8="",$F8=""),"",IFERROR(INDEX(Productos!$I$5:$I$504,MATCH($C8,Productos!$A$5:$A$504,0)),0)+SUMIFS($F$5:$F8,$C$5:$C8,$C8,$B$5:$B8,"Entrada")-SUMIFS($F$5:$F8,$C$5:$C8,$C8,$B$5:$B8,"Salida")) -> 270 | J8: Factura B-0907 | K8: Almacén | M8: =IF(AND($C8<>"",$C8=Kardex!$C$4),COUNTIF($C$5:$C8,Kardex!$C$4),"")
A9: 46302 | B9: Salida | C9: P-002 | D9: =IF($C9="","",IFERROR(INDEX(Productos!$B$5:$B$504,MATCH($C9,Productos!$A$5:$A$504,0)),"Clave no existe")) -> Varilla corrugada 3/8" | E9: =IF($C9="","",IFERROR(INDEX(Productos!$D$5:$D$504,MATCH($C9,Productos!$A$5:$A$504,0)),"")) -> Pieza | F9: 210 | G9: =IF($C9="","",IFERROR(INDEX(Productos!$F$5:$F$504,MATCH($C9,Productos!$A$5:$A$504,0)),0)) -> 168 | H9: =IF(OR($C9="",$F9=""),"",F9*G9) -> 35280 | I9: =IF(OR($C9="",$F9=""),"",IFERROR(INDEX(Productos!$I$5:$I$504,MATCH($C9,Productos!$A$5:$A$504,0)),0)+SUMIFS($F$5:$F9,$C$5:$C9,$C9,$B$5:$B9,"Entrada")-SUMIFS($F$5:$F9,$C$5:$C9,$C9,$B$5:$B9,"Salida")) -> 60 | J9: Pedido 0458 | K9: Ventas | M9: =IF(AND($C9<>"",$C9=Kardex!$C$4),COUNTIF($C$5:$C9,Kardex!$C$4),"")
A10: 46304 | B10: Salida | C10: P-005 | D10: =IF($C10="","",IFERROR(INDEX(Productos!$B$5:$B$504,MATCH($C10,Productos!$A$5:$A$504,0)),"Clave no existe")) -> Pintura vinílica blanca 19 L | E10: =IF($C10="","",IFERROR(INDEX(Productos!$D$5:$D$504,MATCH($C10,Productos!$A$5:$A$504,0)),"")) -> Cubeta | F10: 4 | G10: =IF($C10="","",IFERROR(INDEX(Productos!$F$5:$F$504,MATCH($C10,Productos!$A$5:$A$504,0)),0)) -> 1150 | H10: =IF(OR($C10="",$F10=""),"",F10*G10) -> 4600 | I10: =IF(OR($C10="",$F10=""),"",IFERROR(INDEX(Productos!$I$5:$I$504,MATCH($C10,Productos!$A$5:$A$504,0)),0)+SUMIFS($F$5:$F10,$C$5:$C10,$C10,$B$5:$B10,"Entrada")-SUMIFS($F$5:$F10,$C$5:$C10,$C10,$B$5:$B10,"Salida")) -> 4 | J10: Pedido 0461 | K10: Ventas | M10: =IF(AND($C10<>"",$C10=Kardex!$C$4),COUNTIF($C$5:$C10,Kardex!$C$4),"")
A11: 46305 | B11: Salida | C11: P-001 | D11: =IF($C11="","",IFERROR(INDEX(Productos!$B$5:$B$504,MATCH($C11,Productos!$A$5:$A$504,0)),"Clave no existe")) -> Cemento gris 50 kg | E11: =IF($C11="","",IFERROR(INDEX(Productos!$D$5:$D$504,MATCH($C11,Productos!$A$5:$A$504,0)),"")) -> Bulto | F11: 50 | G11: =IF($C11="","",IFERROR(INDEX(Productos!$F$5:$F$504,MATCH($C11,Productos!$A$5:$A$504,0)),0)) -> 215 | H11: =IF(OR($C11="",$F11=""),"",F11*G11) -> 10750 | I11: =IF(OR($C11="",$F11=""),"",IFERROR(INDEX(Productos!$I$5:$I$504,MATCH($C11,Productos!$A$5:$A$504,0)),0)+SUMIFS($F$5:$F11,$C$5:$C11,$C11,$B$5:$B11,"Entrada")-SUMIFS($F$5:$F11,$C$5:$C11,$C11,$B$5:$B11,"Salida")) -> 55 | J11: Pedido 0463 | K11: Ventas | M11: =IF(AND($C11<>"",$C11=Kardex!$C$4),COUNTIF($C$5:$C11,Kardex!$C$4),"") -> 3
A12: 46308 | B12: Entrada | C12: P-004 | D12: =IF($C12="","",IFERROR(INDEX(Productos!$B$5:$B$504,MATCH($C12,Productos!$A$5:$A$504,0)),"Clave no existe")) -> Tubo PVC hidráulico 1/2" | E12: =IF($C12="","",IFERROR(INDEX(Productos!$D$5:$D$504,MATCH($C12,Productos!$A$5:$A$504,0)),"")) -> Tramo | F12: 40 | G12: =IF($C12="","",IFERROR(INDEX(Productos!$F$5:$F$504,MATCH($C12,Productos!$A$5:$A$504,0)),0)) -> 62 | H12: =IF(OR($C12="",$F12=""),"",F12*G12) -> 2480 | I12: =IF(OR($C12="",$F12=""),"",IFERROR(INDEX(Productos!$I$5:$I$504,MATCH($C12,Productos!$A$5:$A$504,0)),0)+SUMIFS($F$5:$F12,$C$5:$C12,$C12,$B$5:$B12,"Entrada")-SUMIFS($F$5:$F12,$C$5:$C12,$C12,$B$5:$B12,"Salida")) -> 85 | J12: Factura C-2210 | K12: Almacén | M12: =IF(AND($C12<>"",$C12=Kardex!$C$4),COUNTIF($C$5:$C12,Kardex!$C$4),"")
A13: 46309 | B13: Salida | C13: P-004 | D13: =IF($C13="","",IFERROR(INDEX(Productos!$B$5:$B$504,MATCH($C13,Productos!$A$5:$A$504,0)),"Clave no existe")) -> Tubo PVC hidráulico 1/2" | E13: =IF($C13="","",IFERROR(INDEX(Productos!$D$5:$D$504,MATCH($C13,Productos!$A$5:$A$504,0)),"")) -> Tramo | F13: 52 | G13: =IF($C13="","",IFERROR(INDEX(Productos!$F$5:$F$504,MATCH($C13,Productos!$A$5:$A$504,0)),0)) -> 62 | H13: =IF(OR($C13="",$F13=""),"",F13*G13) -> 3224 | I13: =IF(OR($C13="",$F13=""),"",IFERROR(INDEX(Productos!$I$5:$I$504,MATCH($C13,Productos!$A$5:$A$504,0)),0)+SUMIFS($F$5:$F13,$C$5:$C13,$C13,$B$5:$B13,"Entrada")-SUMIFS($F$5:$F13,$C$5:$C13,$C13,$B$5:$B13,"Salida")) -> 33 | J13: Pedido 0470 | K13: Ventas | M13: =IF(AND($C13<>"",$C13=Kardex!$C$4),COUNTIF($C$5:$C13,Kardex!$C$4),"")
A14: 46311 | B14: Salida | C14: P-007 | D14: =IF($C14="","",IFERROR(INDEX(Productos!$B$5:$B$504,MATCH($C14,Productos!$A$5:$A$504,0)),"Clave no existe")) -> Cable THW calibre 12 | E14: =IF($C14="","",IFERROR(INDEX(Productos!$D$5:$D$504,MATCH($C14,Productos!$A$5:$A$504,0)),"")) -> Rollo 100 m | F14: 3 | G14: =IF($C14="","",IFERROR(INDEX(Productos!$F$5:$F$504,MATCH($C14,Productos!$A$5:$A$504,0)),0)) -> 980 | H14: =IF(OR($C14="",$F14=""),"",F14*G14) -> 2940 | I14: =IF(OR($C14="",$F14=""),"",IFERROR(INDEX(Productos!$I$5:$I$504,MATCH($C14,Productos!$A$5:$A$504,0)),0)+SUMIFS($F$5:$F14,$C$5:$C14,$C14,$B$5:$B14,"Entrada")-SUMIFS($F$5:$F14,$C$5:$C14,$C14,$B$5:$B14,"Salida")) -> 0 | J14: Pedido 0474 | K14: Ventas | M14: =IF(AND($C14<>"",$C14=Kardex!$C$4),COUNTIF($C$5:$C14,Kardex!$C$4),"")
A15: 46315 | B15: Salida | C15: P-006 | D15: =IF($C15="","",IFERROR(INDEX(Productos!$B$5:$B$504,MATCH($C15,Productos!$A$5:$A$504,0)),"Clave no existe")) -> Alambre recocido | E15: =IF($C15="","",IFERROR(INDEX(Productos!$D$5:$D$504,MATCH($C15,Productos!$A$5:$A$504,0)),"")) -> Kg | F15: 25 | G15: =IF($C15="","",IFERROR(INDEX(Productos!$F$5:$F$504,MATCH($C15,Productos!$A$5:$A$504,0)),0)) -> 38 | H15: =IF(OR($C15="",$F15=""),"",F15*G15) -> 950 | I15: =IF(OR($C15="",$F15=""),"",IFERROR(INDEX(Productos!$I$5:$I$504,MATCH($C15,Productos!$A$5:$A$504,0)),0)+SUMIFS($F$5:$F15,$C$5:$C15,$C15,$B$5:$B15,"Entrada")-SUMIFS($F$5:$F15,$C$5:$C15,$C15,$B$5:$B15,"Salida")) -> 35 | J15: Pedido 0480 | K15: Ventas | M15: =IF(AND($C15<>"",$C15=Kardex!$C$4),COUNTIF($C$5:$C15,Kardex!$C$4),"")
A16: 46316 | B16: Entrada | C16: P-008 | D16: =IF($C16="","",IFERROR(INDEX(Productos!$B$5:$B$504,MATCH($C16,Productos!$A$5:$A$504,0)),"Clave no existe")) -> Tornillo para tablaroca 1" | E16: =IF($C16="","",IFERROR(INDEX(Productos!$D$5:$D$504,MATCH($C16,Productos!$A$5:$A$504,0)),"")) -> Caja 1000 | F16: 10 | G16: =IF($C16="","",IFERROR(INDEX(Productos!$F$5:$F$504,MATCH($C16,Productos!$A$5:$A$504,0)),0)) -> 145 | H16: =IF(OR($C16="",$F16=""),"",F16*G16) -> 1450 | I16: =IF(OR($C16="",$F16=""),"",IFERROR(INDEX(Productos!$I$5:$I$504,MATCH($C16,Productos!$A$5:$A$504,0)),0)+SUMIFS($F$5:$F16,$C$5:$C16,$C16,$B$5:$B16,"Entrada")-SUMIFS($F$5:$F16,$C$5:$C16,$C16,$B$5:$B16,"Salida")) -> 32 | J16: Factura A-1240 | K16: Almacén | M16: =IF(AND($C16<>"",$C16=Kardex!$C$4),COUNTIF($C$5:$C16,Kardex!$C$4),"")
... A18: 46322 | B18: Salida | C18: P-003 | D18: =IF($C18="","",IFERROR(INDEX(Productos!$B$5:$B$504,MATCH($C18,Productos!$A$5:$A$504,0)),"Clave no existe")) -> Block de concreto 15x20x40 | E18: =IF($C18="","",IFERROR(INDEX(Productos!$D$5:$D$504,MATCH($C18,Productos!$A$5:$A$504,0)),"")) -> Pieza | F18: 380 | G18: =IF($C18="","",IFERROR(INDEX(Productos!$F$5:$F$504,MATCH($C18,Productos!$A$5:$A$504,0)),0)) -> 14.5 | H18: =IF(OR($C18="",$F18=""),"",F18*G18) -> 5510 | I18: =IF(OR($C18="",$F18=""),"",IFERROR(INDEX(Productos!$I$5:$I$504,MATCH($C18,Productos!$A$5:$A$504,0)),0)+SUMIFS($F$5:$F18,$C$5:$C18,$C18,$B$5:$B18,"Entrada")-SUMIFS($F$5:$F18,$C$5:$C18,$C18,$B$5:$B18,"Salida")) -> 420 | J18: Pedido 0491 | K18: Ventas | M18: =IF(AND($C18<>"",$C18=Kardex!$C$4),COUNTIF($C$5:$C18,Kardex!$C$4),"")
D19: =IF($C19="","",IFERROR(INDEX(Productos!$B$5:$B$504,MATCH($C19,Productos!$A$5:$A$504,0)),"Clave no existe")) | E19: =IF($C19="","",IFERROR(INDEX(Productos!$D$5:$D$504,MATCH($C19,Productos!$A$5:$A$504,0)),"")) | G19: =IF($C19="","",IFERROR(INDEX(Productos!$F$5:$F$504,MATCH($C19,Productos!$A$5:$A$504,0)),0)) | H19: =IF(OR($C19="",$F19=""),"",F19*G19) | I19: =IF(OR($C19="",$F19=""),"",IFERROR(INDEX(Productos!$I$5:$I$504,MATCH($C19,Productos!$A$5:$A$504,0)),0)+SUMIFS($F$5:$F19,$C$5:$C19,$C19,$B$5:$B19,"Entrada")-SUMIFS($F$5:$F19,$C$5:$C19,$C19,$B$5:$B19,"Salida")) | M19: =IF(AND($C19<>"",$C19=Kardex!$C$4),COUNTIF($C$5:$C19,Kardex!$C$4),"")
D20: =IF($C20="","",IFERROR(INDEX(Productos!$B$5:$B$504,MATCH($C20,Productos!$A$5:$A$504,0)),"Clave no existe")) | E20: =IF($C20="","",IFERROR(INDEX(Productos!$D$5:$D$504,MATCH($C20,Productos!$A$5:$A$504,0)),"")) | G20: =IF($C20="","",IFERROR(INDEX(Productos!$F$5:$F$504,MATCH($C20,Productos!$A$5:$A$504,0)),0)) | H20: =IF(OR($C20="",$F20=""),"",F20*G20) | I20: =IF(OR($C20="",$F20=""),"",IFERROR(INDEX(Productos!$I$5:$I$504,MATCH($C20,Productos!$A$5:$A$504,0)),0)+SUMIFS($F$5:$F20,$C$5:$C20,$C20,$B$5:$B20,"Entrada")-SUMIFS($F$5:$F20,$C$5:$C20,$C20,$B$5:$B20,"Salida")) | M20: =IF(AND($C20<>"",$C20=Kardex!$C$4),COUNTIF($C$5:$C20,Kardex!$C$4),"")
D21: =IF($C21="","",IFERROR(INDEX(Productos!$B$5:$B$504,MATCH($C21,Productos!$A$5:$A$504,0)),"Clave no existe")) | E21: =IF($C21="","",IFERROR(INDEX(Productos!$D$5:$D$504,MATCH($C21,Productos!$A$5:$A$504,0)),"")) | G21: =IF($C21="","",IFERROR(INDEX(Productos!$F$5:$F$504,MATCH($C21,Productos!$A$5:$A$504,0)),0)) | H21: =IF(OR($C21="",$F21=""),"",F21*G21) | I21: =IF(OR($C21="",$F21=""),"",IFERROR(INDEX(Productos!$I$5:$I$504,MATCH($C21,Productos!$A$5:$A$504,0)),0)+SUMIFS($F$5:$F21,$C$5:$C21,$C21,$B$5:$B21,"Entrada")-SUMIFS($F$5:$F21,$C$5:$C21,$C21,$B$5:$B21,"Salida")) | M21: =IF(AND($C21<>"",$C21=Kardex!$C$4),COUNTIF($C$5:$C21,Kardex!$C$4),"")
D22: =IF($C22="","",IFERROR(INDEX(Productos!$B$5:$B$504,MATCH($C22,Productos!$A$5:$A$504,0)),"Clave no existe")) | E22: =IF($C22="","",IFERROR(INDEX(Productos!$D$5:$D$504,MATCH($C22,Productos!$A$5:$A$504,0)),"")) | G22: =IF($C22="","",IFERROR(INDEX(Productos!$F$5:$F$504,MATCH($C22,Productos!$A$5:$A$504,0)),0)) | H22: =IF(OR($C22="",$F22=""),"",F22*G22) | I22: =IF(OR($C22="",$F22=""),"",IFERROR(INDEX(Productos!$I$5:$I$504,MATCH($C22,Productos!$A$5:$A$504,0)),0)+SUMIFS($F$5:$F22,$C$5:$C22,$C22,$B$5:$B22,"Entrada")-SUMIFS($F$5:$F22,$C$5:$C22,$C22,$B$5:$B22,"Salida")) | M22: =IF(AND($C22<>"",$C22=Kardex!$C$4),COUNTIF($C$5:$C22,Kardex!$C$4),"")
D23: =IF($C23="","",IFERROR(INDEX(Productos!$B$5:$B$504,MATCH($C23,Productos!$A$5:$A$504,0)),"Clave no existe")) | E23: =IF($C23="","",IFERROR(INDEX(Productos!$D$5:$D$504,MATCH($C23,Productos!$A$5:$A$504,0)),"")) | G23: =IF($C23="","",IFERROR(INDEX(Productos!$F$5:$F$504,MATCH($C23,Productos!$A$5:$A$504,0)),0)) | H23: =IF(OR($C23="",$F23=""),"",F23*G23) | I23: =IF(OR($C23="",$F23=""),"",IFERROR(INDEX(Productos!$I$5:$I$504,MATCH($C23,Productos!$A$5:$A$504,0)),0)+SUMIFS($F$5:$F23,$C$5:$C23,$C23,$B$5:$B23,"Entrada")-SUMIFS($F$5:$F23,$C$5:$C23,$C23,$B$5:$B23,"Salida")) | M23: =IF(AND($C23<>"",$C23=Kardex!$C$4),COUNTIF($C$5:$C23,Kardex!$C$4),"")
D24: =IF($C24="","",IFERROR(INDEX(Productos!$B$5:$B$504,MATCH($C24,Productos!$A$5:$A$504,0)),"Clave no existe")) | E24: =IF($C24="","",IFERROR(INDEX(Productos!$D$5:$D$504,MATCH($C24,Productos!$A$5:$A$504,0)),"")) | G24: =IF($C24="","",IFERROR(INDEX(Productos!$F$5:$F$504,MATCH($C24,Productos!$A$5:$A$504,0)),0)) | H24: =IF(OR($C24="",$F24=""),"",F24*G24) | I24: =IF(OR($C24="",$F24=""),"",IFERROR(INDEX(Productos!$I$5:$I$504,MATCH($C24,Productos!$A$5:$A$504,0)),0)+SUMIFS($F$5:$F24,$C$5:$C24,$C24,$B$5:$B24,"Entrada")-SUMIFS($F$5:$F24,$C$5:$C24,$C24,$B$5:$B24,"Salida")) | M24: =IF(AND($C24<>"",$C24=Kardex!$C$4),COUNTIF($C$5:$C24,Kardex!$C$4),"")
D25: =IF($C25="","",IFERROR(INDEX(Productos!$B$5:$B$504,MATCH($C25,Productos!$A$5:$A$504,0)),"Clave no existe")) | E25: =IF($C25="","",IFERROR(INDEX(Productos!$D$5:$D$504,MATCH($C25,Productos!$A$5:$A$504,0)),"")) | G25: =IF($C25="","",IFERROR(INDEX(Productos!$F$5:$F$504,MATCH($C25,Productos!$A$5:$A$504,0)),0)) | H25: =IF(OR($C25="",$F25=""),"",F25*G25) | I25: =IF(OR($C25="",$F25=""),"",IFERROR(INDEX(Productos!$I$5:$I$504,MATCH($C25,Productos!$A$5:$A$504,0)),0)+SUMIFS($F$5:$F25,$C$5:$C25,$C25,$B$5:$B25,"Entrada")-SUMIFS($F$5:$F25,$C$5:$C25,$C25,$B$5:$B25,"Salida")) | M25: =IF(AND($C25<>"",$C25=Kardex!$C$4),COUNTIF($C$5:$C25,Kardex!$C$4),"")
D26: =IF($C26="","",IFERROR(INDEX(Productos!$B$5:$B$504,MATCH($C26,Productos!$A$5:$A$504,0)),"Clave no existe")) | E26: =IF($C26="","",IFERROR(INDEX(Productos!$D$5:$D$504,MATCH($C26,Productos!$A$5:$A$504,0)),"")) | G26: =IF($C26="","",IFERROR(INDEX(Productos!$F$5:$F$504,MATCH($C26,Productos!$A$5:$A$504,0)),0)) | H26: =IF(OR($C26="",$F26=""),"",F26*G26) | I26: =IF(OR($C26="",$F26=""),"",IFERROR(INDEX(Productos!$I$5:$I$504,MATCH($C26,Productos!$A$5:$A$504,0)),0)+SUMIFS($F$5:$F26,$C$5:$C26,$C26,$B$5:$B26,"Entrada")-SUMIFS($F$5:$F26,$C$5:$C26,$C26,$B$5:$B26,"Salida")) | M26: =IF(AND($C26<>"",$C26=Kardex!$C$4),COUNTIF($C$5:$C26,Kardex!$C$4),"")
D27: =IF($C27="","",IFERROR(INDEX(Productos!$B$5:$B$504,MATCH($C27,Productos!$A$5:$A$504,0)),"Clave no existe")) | E27: =IF($C27="","",IFERROR(INDEX(Productos!$D$5:$D$504,MATCH($C27,Productos!$A$5:$A$504,0)),"")) | G27: =IF($C27="","",IFERROR(INDEX(Productos!$F$5:$F$504,MATCH($C27,Productos!$A$5:$A$504,0)),0)) | H27: =IF(OR($C27="",$F27=""),"",F27*G27) | I27: =IF(OR($C27="",$F27=""),"",IFERROR(INDEX(Productos!$I$5:$I$504,MATCH($C27,Productos!$A$5:$A$504,0)),0)+SUMIFS($F$5:$F27,$C$5:$C27,$C27,$B$5:$B27,"Entrada")-SUMIFS($F$5:$F27,$C$5:$C27,$C27,$B$5:$B27,"Salida")) | M27: =IF(AND($C27<>"",$C27=Kardex!$C$4),COUNTIF($C$5:$C27,Kardex!$C$4),"")
D28: =IF($C28="","",IFERROR(INDEX(Productos!$B$5:$B$504,MATCH($C28,Productos!$A$5:$A$504,0)),"Clave no existe")) | E28: =IF($C28="","",IFERROR(INDEX(Productos!$D$5:$D$504,MATCH($C28,Productos!$A$5:$A$504,0)),"")) | G28: =IF($C28="","",IFERROR(INDEX(Productos!$F$5:$F$504,MATCH($C28,Productos!$A$5:$A$504,0)),0)) | H28: =IF(OR($C28="",$F28=""),"",F28*G28) | I28: =IF(OR($C28="",$F28=""),"",IFERROR(INDEX(Productos!$I$5:$I$504,MATCH($C28,Productos!$A$5:$A$504,0)),0)+SUMIFS($F$5:$F28,$C$5:$C28,$C28,$B$5:$B28,"Entrada")-SUMIFS($F$5:$F28,$C$5:$C28,$C28,$B$5:$B28,"Salida")) | M28: =IF(AND($C28<>"",$C28=Kardex!$C$4),COUNTIF($C$5:$C28,Kardex!$C$4),"")
D29: =IF($C29="","",IFERROR(INDEX(Productos!$B$5:$B$504,MATCH($C29,Productos!$A$5:$A$504,0)),"Clave no existe")) | E29: =IF($C29="","",IFERROR(INDEX(Productos!$D$5:$D$504,MATCH($C29,Productos!$A$5:$A$504,0)),"")) | G29: =IF($C29="","",IFERROR(INDEX(Productos!$F$5:$F$504,MATCH($C29,Productos!$A$5:$A$504,0)),0)) | H29: =IF(OR($C29="",$F29=""),"",F29*G29) | I29: =IF(OR($C29="",$F29=""),"",IFERROR(INDEX(Productos!$I$5:$I$504,MATCH($C29,Productos!$A$5:$A$504,0)),0)+SUMIFS($F$5:$F29,$C$5:$C29,$C29,$B$5:$B29,"Entrada")-SUMIFS($F$5:$F29,$C$5:$C29,$C29,$B$5:$B29,"Salida")) | M29: =IF(AND($C29<>"",$C29=Kardex!$C$4),COUNTIF($C$5:$C29,Kardex!$C$4),"")
D30: =IF($C30="","",IFERROR(INDEX(Productos!$B$5:$B$504,MATCH($C30,Productos!$A$5:$A$504,0)),"Clave no existe")) | E30: =IF($C30="","",IFERROR(INDEX(Productos!$D$5:$D$504,MATCH($C30,Productos!$A$5:$A$504,0)),"")) | G30: =IF($C30="","",IFERROR(INDEX(Productos!$F$5:$F$504,MATCH($C30,Productos!$A$5:$A$504,0)),0)) | H30: =IF(OR($C30="",$F30=""),"",F30*G30) | I30: =IF(OR($C30="",$F30=""),"",IFERROR(INDEX(Productos!$I$5:$I$504,MATCH($C30,Productos!$A$5:$A$504,0)),0)+SUMIFS($F$5:$F30,$C$5:$C30,$C30,$B$5:$B30,"Entrada")-SUMIFS($F$5:$F30,$C$5:$C30,$C30,$B$5:$B30,"Salida")) | M30: =IF(AND($C30<>"",$C30=Kardex!$C$4),COUNTIF($C$5:$C30,Kardex!$C$4),"")
... D3004: =IF($C3004="","",IFERROR(INDEX(Productos!$B$5:$B$504,MATCH($C3004,Productos!$A$5:$A$504,0)),"Clave no existe")) | E3004: =IF($C3004="","",IFERROR(INDEX(Productos!$D$5:$D$504,MATCH($C3004,Productos!$A$5:$A$504,0)),"")) | G3004: =IF($C3004="","",IFERROR(INDEX(Productos!$F$5:$F$504,MATCH($C3004,Productos!$A$5:$A$504,0)),0)) | H3004: =IF(OR($C3004="",$F3004=""),"",F3004*G3004) | I3004: =IF(OR($C3004="",$F3004=""),"",IFERROR(INDEX(Productos!$I$5:$I$504,MATCH($C3004,Productos!$A$5:$A$504,0)),0)+SUMIFS($F$5:$F3004,$C$5:$C3004,$C3004,$B$5:$B3004,"Entrada")-SUMIFS($F$5:$F3004,$C$5:$C3004,$C3004,$B$5:$B3004,"Salida")) | M3004: =IF(AND($C3004<>"",$C3004=Kardex!$C$4),COUNTIF($C$5:$C3004,Kardex!$C$4),"")

Sheet Kardex
A1: Kardex por artículo
A2: Elige una clave en la celda amarilla y verás todos sus movimientos con la existencia después de cada uno.
B4: Clave: | C4: P-001 | D4: =IF($C$4="","",IFERROR(INDEX(Productos!$B$5:$B$504,MATCH($C$4,Productos!$A$5:$A$504,0)),"Clave no existe")) -> Cemento gris 50 kg
B5: Existencia inicial: | C5: =IF($C$4="","",IFERROR(INDEX(Productos!$I$5:$I$504,MATCH($C$4,Productos!$A$5:$A$504,0)),0)) -> 80
B6: Existencia actual: | C6: =IF($C$4="","",IFERROR(INDEX(Productos!$L$5:$L$504,MATCH($C$4,Productos!$A$5:$A$504,0)),0)) -> 55
A8: # | B8: Fecha | C8: Tipo | D8: Referencia | E8: Entrada | F8: Salida | G8: Existencia | H8: Costo unitario | I8: Importe | J8: Responsable
A9: =IF(1<=COUNTIF(Movimientos!$M$5:$M$3004,">0"),1,"") -> 1 | B9: =IF($A9="","",INDEX(Movimientos!$A$5:$A$3004,MATCH($A9,Movimientos!$M$5:$M$3004,0))) -> 46296 | C9: =IF($A9="","",INDEX(Movimientos!$B$5:$B$3004,MATCH($A9,Movimientos!$M$5:$M$3004,0))) -> Entrada | D9: =IF($A9="","",INDEX(Movimientos!$J$5:$J$3004,MATCH($A9,Movimientos!$M$5:$M$3004,0))&"") -> Factura A-1182 | E9: =IF($A9="","",IF(C9="Entrada",INDEX(Movimientos!$F$5:$F$3004,MATCH($A9,Movimientos!$M$5:$M$3004,0)),"")) -> 60 | F9: =IF($A9="","",IF(C9="Salida",INDEX(Movimientos!$F$5:$F$3004,MATCH($A9,Movimientos!$M$5:$M$3004,0)),"")) | G9: =IF($A9="","",INDEX(Movimientos!$I$5:$I$3004,MATCH($A9,Movimientos!$M$5:$M$3004,0))) -> 140 | H9: =IF($A9="","",INDEX(Movimientos!$G$5:$G$3004,MATCH($A9,Movimientos!$M$5:$M$3004,0))) -> 215 | I9: =IF($A9="","",INDEX(Movimientos!$H$5:$H$3004,MATCH($A9,Movimientos!$M$5:$M$3004,0))) -> 12900 | J9: =IF($A9="","",INDEX(Movimientos!$K$5:$K$3004,MATCH($A9,Movimientos!$M$5:$M$3004,0))&"") -> Almacén
A10: =IF(2<=COUNTIF(Movimientos!$M$5:$M$3004,">0"),2,"") -> 2 | B10: =IF($A10="","",INDEX(Movimientos!$A$5:$A$3004,MATCH($A10,Movimientos!$M$5:$M$3004,0))) -> 46297 | C10: =IF($A10="","",INDEX(Movimientos!$B$5:$B$3004,MATCH($A10,Movimientos!$M$5:$M$3004,0))) -> Salida | D10: =IF($A10="","",INDEX(Movimientos!$J$5:$J$3004,MATCH($A10,Movimientos!$M$5:$M$3004,0))&"") -> Pedido 0451 | E10: =IF($A10="","",IF(C10="Entrada",INDEX(Movimientos!$F$5:$F$3004,MATCH($A10,Movimientos!$M$5:$M$3004,0)),"")) | F10: =IF($A10="","",IF(C10="Salida",INDEX(Movimientos!$F$5:$F$3004,MATCH($A10,Movimientos!$M$5:$M$3004,0)),"")) -> 35 | G10: =IF($A10="","",INDEX(Movimientos!$I$5:$I$3004,MATCH($A10,Movimientos!$M$5:$M$3004,0))) -> 105 | H10: =IF($A10="","",INDEX(Movimientos!$G$5:$G$3004,MATCH($A10,Movimientos!$M$5:$M$3004,0))) -> 215 | I10: =IF($A10="","",INDEX(Movimientos!$H$5:$H$3004,MATCH($A10,Movimientos!$M$5:$M$3004,0))) -> 7525 | J10: =IF($A10="","",INDEX(Movimientos!$K$5:$K$3004,MATCH($A10,Movimientos!$M$5:$M$3004,0))&"") -> Ventas
A11: =IF(3<=COUNTIF(Movimientos!$M$5:$M$3004,">0"),3,"") -> 3 | B11: =IF($A11="","",INDEX(Movimientos!$A$5:$A$3004,MATCH($A11,Movimientos!$M$5:$M$3004,0))) -> 46305 | C11: =IF($A11="","",INDEX(Movimientos!$B$5:$B$3004,MATCH($A11,Movimientos!$M$5:$M$3004,0))) -> Salida | D11: =IF($A11="","",INDEX(Movimientos!$J$5:$J$3004,MATCH($A11,Movimientos!$M$5:$M$3004,0))&"") -> Pedido 0463 | E11: =IF($A11="","",IF(C11="Entrada",INDEX(Movimientos!$F$5:$F$3004,MATCH($A11,Movimientos!$M$5:$M$3004,0)),"")) | F11: =IF($A11="","",IF(C11="Salida",INDEX(Movimientos!$F$5:$F$3004,MATCH($A11,Movimientos!$M$5:$M$3004,0)),"")) -> 50 | G11: =IF($A11="","",INDEX(Movimientos!$I$5:$I$3004,MATCH($A11,Movimientos!$M$5:$M$3004,0))) -> 55 | H11: =IF($A11="","",INDEX(Movimientos!$G$5:$G$3004,MATCH($A11,Movimientos!$M$5:$M$3004,0))) -> 215 | I11: =IF($A11="","",INDEX(Movimientos!$H$5:$H$3004,MATCH($A11,Movimientos!$M$5:$M$3004,0))) -> 10750 | J11: =IF($A11="","",INDEX(Movimientos!$K$5:$K$3004,MATCH($A11,Movimientos!$M$5:$M$3004,0))&"") -> Ventas
A12: =IF(4<=COUNTIF(Movimientos!$M$5:$M$3004,">0"),4,"") | B12: =IF($A12="","",INDEX(Movimientos!$A$5:$A$3004,MATCH($A12,Movimientos!$M$5:$M$3004,0))) | C12: =IF($A12="","",INDEX(Movimientos!$B$5:$B$3004,MATCH($A12,Movimientos!$M$5:$M$3004,0))) | D12: =IF($A12="","",INDEX(Movimientos!$J$5:$J$3004,MATCH($A12,Movimientos!$M$5:$M$3004,0))&"") | E12: =IF($A12="","",IF(C12="Entrada",INDEX(Movimientos!$F$5:$F$3004,MATCH($A12,Movimientos!$M$5:$M$3004,0)),"")) | F12: =IF($A12="","",IF(C12="Salida",INDEX(Movimientos!$F$5:$F$3004,MATCH($A12,Movimientos!$M$5:$M$3004,0)),"")) | G12: =IF($A12="","",INDEX(Movimientos!$I$5:$I$3004,MATCH($A12,Movimientos!$M$5:$M$3004,0))) | H12: =IF($A12="","",INDEX(Movimientos!$G$5:$G$3004,MATCH($A12,Movimientos!$M$5:$M$3004,0))) | I12: =IF($A12="","",INDEX(Movimientos!$H$5:$H$3004,MATCH($A12,Movimientos!$M$5:$M$3004,0))) | J12: =IF($A12="","",INDEX(Movimientos!$K$5:$K$3004,MATCH($A12,Movimientos!$M$5:$M$3004,0))&"")
A13: =IF(5<=COUNTIF(Movimientos!$M$5:$M$3004,">0"),5,"") | B13: =IF($A13="","",INDEX(Movimientos!$A$5:$A$3004,MATCH($A13,Movimientos!$M$5:$M$3004,0))) | C13: =IF($A13="","",INDEX(Movimientos!$B$5:$B$3004,MATCH($A13,Movimientos!$M$5:$M$3004,0))) | D13: =IF($A13="","",INDEX(Movimientos!$J$5:$J$3004,MATCH($A13,Movimientos!$M$5:$M$3004,0))&"") | E13: =IF($A13="","",IF(C13="Entrada",INDEX(Movimientos!$F$5:$F$3004,MATCH($A13,Movimientos!$M$5:$M$3004,0)),"")) | F13: =IF($A13="","",IF(C13="Salida",INDEX(Movimientos!$F$5:$F$3004,MATCH($A13,Movimientos!$M$5:$M$3004,0)),"")) | G13: =IF($A13="","",INDEX(Movimientos!$I$5:$I$3004,MATCH($A13,Movimientos!$M$5:$M$3004,0))) | H13: =IF($A13="","",INDEX(Movimientos!$G$5:$G$3004,MATCH($A13,Movimientos!$M$5:$M$3004,0))) | I13: =IF($A13="","",INDEX(Movimientos!$H$5:$H$3004,MATCH($A13,Movimientos!$M$5:$M$3004,0))) | J13: =IF($A13="","",INDEX(Movimientos!$K$5:$K$3004,MATCH($A13,Movimientos!$M$5:$M$3004,0))&"")
A14: =IF(6<=COUNTIF(Movimientos!$M$5:$M$3004,">0"),6,"") | B14: =IF($A14="","",INDEX(Movimientos!$A$5:$A$3004,MATCH($A14,Movimientos!$M$5:$M$3004,0))) | C14: =IF($A14="","",INDEX(Movimientos!$B$5:$B$3004,MATCH($A14,Movimientos!$M$5:$M$3004,0))) | D14: =IF($A14="","",INDEX(Movimientos!$J$5:$J$3004,MATCH($A14,Movimientos!$M$5:$M$3004,0))&"") | E14: =IF($A14="","",IF(C14="Entrada",INDEX(Movimientos!$F$5:$F$3004,MATCH($A14,Movimientos!$M$5:$M$3004,0)),"")) | F14: =IF($A14="","",IF(C14="Salida",INDEX(Movimientos!$F$5:$F$3004,MATCH($A14,Movimientos!$M$5:$M$3004,0)),"")) | G14: =IF($A14="","",INDEX(Movimientos!$I$5:$I$3004,MATCH($A14,Movimientos!$M$5:$M$3004,0))) | H14: =IF($A14="","",INDEX(Movimientos!$G$5:$G$3004,MATCH($A14,Movimientos!$M$5:$M$3004,0))) | I14: =IF($A14="","",INDEX(Movimientos!$H$5:$H$3004,MATCH($A14,Movimientos!$M$5:$M$3004,0))) | J14: =IF($A14="","",INDEX(Movimientos!$K$5:$K$3004,MATCH($A14,Movimientos!$M$5:$M$3004,0))&"")
A15: =IF(7<=COUNTIF(Movimientos!$M$5:$M$3004,">0"),7,"") | B15: =IF($A15="","",INDEX(Movimientos!$A$5:$A$3004,MATCH($A15,Movimientos!$M$5:$M$3004,0))) | C15: =IF($A15="","",INDEX(Movimientos!$B$5:$B$3004,MATCH($A15,Movimientos!$M$5:$M$3004,0))) | D15: =IF($A15="","",INDEX(Movimientos!$J$5:$J$3004,MATCH($A15,Movimientos!$M$5:$M$3004,0))&"") | E15: =IF($A15="","",IF(C15="Entrada",INDEX(Movimientos!$F$5:$F$3004,MATCH($A15,Movimientos!$M$5:$M$3004,0)),"")) | F15: =IF($A15="","",IF(C15="Salida",INDEX(Movimientos!$F$5:$F$3004,MATCH($A15,Movimientos!$M$5:$M$3004,0)),"")) | G15: =IF($A15="","",INDEX(Movimientos!$I$5:$I$3004,MATCH($A15,Movimientos!$M$5:$M$3004,0))) | H15: =IF($A15="","",INDEX(Movimientos!$G$5:$G$3004,MATCH($A15,Movimientos!$M$5:$M$3004,0))) | I15: =IF($A15="","",INDEX(Movimientos!$H$5:$H$3004,MATCH($A15,Movimientos!$M$5:$M$3004,0))) | J15: =IF($A15="","",INDEX(Movimientos!$K$5:$K$3004,MATCH($A15,Movimientos!$M$5:$M$3004,0))&"")
A16: =IF(8<=COUNTIF(Movimientos!$M$5:$M$3004,">0"),8,"") | B16: =IF($A16="","",INDEX(Movimientos!$A$5:$A$3004,MATCH($A16,Movimientos!$M$5:$M$3004,0))) | C16: =IF($A16="","",INDEX(Movimientos!$B$5:$B$3004,MATCH($A16,Movimientos!$M$5:$M$3004,0))) | D16: =IF($A16="","",INDEX(Movimientos!$J$5:$J$3004,MATCH($A16,Movimientos!$M$5:$M$3004,0))&"") | E16: =IF($A16="","",IF(C16="Entrada",INDEX(Movimientos!$F$5:$F$3004,MATCH($A16,Movimientos!$M$5:$M$3004,0)),"")) | F16: =IF($A16="","",IF(C16="Salida",INDEX(Movimientos!$F$5:$F$3004,MATCH($A16,Movimientos!$M$5:$M$3004,0)),"")) | G16: =IF($A16="","",INDEX(Movimientos!$I$5:$I$3004,MATCH($A16,Movimientos!$M$5:$M$3004,0))) | H16: =IF($A16="","",INDEX(Movimientos!$G$5:$G$3004,MATCH($A16,Movimientos!$M$5:$M$3004,0))) | I16: =IF($A16="","",INDEX(Movimientos!$H$5:$H$3004,MATCH($A16,Movimientos!$M$5:$M$3004,0))) | J16: =IF($A16="","",INDEX(Movimientos!$K$5:$K$3004,MATCH($A16,Movimientos!$M$5:$M$3004,0))&"")
